Workbook

Sheet Synthese
A1: Indicateur | B1: Valeur | D1: Module | E1: Total | F1: OK | G1: KO | H1: % OK | I1: % KO
A2: Total cas | B2: =COUNTA(Cas_de_test!$A$2:$A$9999) -> 122 | D2: Acces et navigation | E2: =COUNTIF(Cas_de_test!$B$2:$B$9999,D2) -> 12 | F2: =COUNTIFS(Cas_de_test!$B$2:$B$9999,D2,Cas_de_test!$K$2:$K$9999,"OK") -> 0 | G2: =COUNTIFS(Cas_de_test!$B$2:$B$9999,D2,Cas_de_test!$K$2:$K$9999,"KO") -> 0 | H2: =IF((F2+G2)=0,0,F2/(F2+G2)) -> 0 | I2: =IF((F2+G2)=0,0,G2/(F2+G2)) -> 0
A3: Cas OK | B3: =COUNTIF(Cas_de_test!$K$2:$K$9999,"OK") -> 0 | D3: Prestataire | E3: =COUNTIF(Cas_de_test!$B$2:$B$9999,D3) -> 14 | F3: =COUNTIFS(Cas_de_test!$B$2:$B$9999,D3,Cas_de_test!$K$2:$K$9999,"OK") -> 0 | G3: =COUNTIFS(Cas_de_test!$B$2:$B$9999,D3,Cas_de_test!$K$2:$K$9999,"KO") -> 0 | H3: =IF((F3+G3)=0,0,F3/(F3+G3)) -> 0 | I3: =IF((F3+G3)=0,0,G3/(F3+G3)) -> 0
A4: Cas KO | B4: =COUNTIF(Cas_de_test!$K$2:$K$9999,"KO") -> 0 | D4: Date | E4: =COUNTIF(Cas_de_test!$B$2:$B$9999,D4) -> 14 | F4: =COUNTIFS(Cas_de_test!$B$2:$B$9999,D4,Cas_de_test!$K$2:$K$9999,"OK") -> 0 | G4: =COUNTIFS(Cas_de_test!$B$2:$B$9999,D4,Cas_de_test!$K$2:$K$9999,"KO") -> 0 | H4: =IF((F4+G4)=0,0,F4/(F4+G4)) -> 0 | I4: =IF((F4+G4)=0,0,G4/(F4+G4)) -> 0
A5: Cas NT | B5: =COUNTIF(Cas_de_test!$K$2:$K$9999,"NT") -> 122 | D5: Rouleaux | E5: =COUNTIF(Cas_de_test!$B$2:$B$9999,D5) -> 18 | F5: =COUNTIFS(Cas_de_test!$B$2:$B$9999,D5,Cas_de_test!$K$2:$K$9999,"OK") -> 0 | G5: =COUNTIFS(Cas_de_test!$B$2:$B$9999,D5,Cas_de_test!$K$2:$K$9999,"KO") -> 0 | H5: =IF((F5+G5)=0,0,F5/(F5+G5)) -> 0 | I5: =IF((F5+G5)=0,0,G5/(F5+G5)) -> 0
A6: Cas executes (OK+KO) | B6: =B3+B4 -> 0 | D6: Prix par rouleau | E6: =COUNTIF(Cas_de_test!$B$2:$B$9999,D6) -> 18 | F6: =COUNTIFS(Cas_de_test!$B$2:$B$9999,D6,Cas_de_test!$K$2:$K$9999,"OK") -> 0 | G6: =COUNTIFS(Cas_de_test!$B$2:$B$9999,D6,Cas_de_test!$K$2:$K$9999,"KO") -> 0 | H6: =IF((F6+G6)=0,0,F6/(F6+G6)) -> 0 | I6: =IF((F6+G6)=0,0,G6/(F6+G6)) -> 0
A7: % Execution | B7: =IF(B2=0,0,B6/B2) -> 0 | D7: Calcul montant | E7: =COUNTIF(Cas_de_test!$B$2:$B$9999,D7) -> 12 | F7: =COUNTIFS(Cas_de_test!$B$2:$B$9999,D7,Cas_de_test!$K$2:$K$9999,"OK") -> 0 | G7: =COUNTIFS(Cas_de_test!$B$2:$B$9999,D7,Cas_de_test!$K$2:$K$9999,"KO") -> 0 | H7: =IF((F7+G7)=0,0,F7/(F7+G7)) -> 0 | I7: =IF((F7+G7)=0,0,G7/(F7+G7)) -> 0
A8: % OK (sur executes) | B8: =IF(B6=0,0,B3/B6) -> 0 | D8: Creation packing | E8: =COUNTIF(Cas_de_test!$B$2:$B$9999,D8) -> 12 | F8: =COUNTIFS(Cas_de_test!$B$2:$B$9999,D8,Cas_de_test!$K$2:$K$9999,"OK") -> 0 | G8: =COUNTIFS(Cas_de_test!$B$2:$B$9999,D8,Cas_de_test!$K$2:$K$9999,"KO") -> 0 | H8: =IF((F8+G8)=0,0,F8/(F8+G8)) -> 0 | I8: =IF((F8+G8)=0,0,G8/(F8+G8)) -> 0
A9: % KO (sur executes) | B9: =IF(B6=0,0,B4/B6) -> 0 | D9: Statut et facture | E9: =COUNTIF(Cas_de_test!$B$2:$B$9999,D9) -> 12 | F9: =COUNTIFS(Cas_de_test!$B$2:$B$9999,D9,Cas_de_test!$K$2:$K$9999,"OK") -> 0 | G9: =COUNTIFS(Cas_de_test!$B$2:$B$9999,D9,Cas_de_test!$K$2:$K$9999,"KO") -> 0 | H9: =IF((F9+G9)=0,0,F9/(F9+G9)) -> 0 | I9: =IF((F9+G9)=0,0,G9/(F9+G9)) -> 0
D10: Securite et robustesse | E10: =COUNTIF(Cas_de_test!$B$2:$B$9999,D10) -> 10 | F10: =COUNTIFS(Cas_de_test!$B$2:$B$9999,D10,Cas_de_test!$K$2:$K$9999,"OK") -> 0 | G10: =COUNTIFS(Cas_de_test!$B$2:$B$9999,D10,Cas_de_test!$K$2:$K$9999,"KO") -> 0 | H10: =IF((F10+G10)=0,0,F10/(F10+G10)) -> 0 | I10: =IF((F10+G10)=0,0,G10/(F10+G10)) -> 0
A12: Mode emploi
A13: 1. Executer les tests de Cas_de_test.
A14: 2. Mettre Statut sur OK, KO ou NT.
A15: 3. Renseigner Resultat obtenu + preuve en cas KO.

Sheet Cas_de_test
A1: ID | B1: Module | C1: Sous-module | D1: Priorite | E1: Type | F1: Preconditions | G1: Etapes | H1: Donnees de test | I1: Resultat attendu | J1: Resultat obtenu | K1: Statut (OK/KO/NT) | L1: Severite anomalie | M1: Capture / preuve | N1: Testeur | O1: Date execution | P1: Commentaires
A2: PACK-001 | B2: Acces et navigation | C2: Ouverture ecran | D2: P1 | E2: Fonctionnel | F2: Utilisateur connecte avec permission packings.create | G2: Ouvrir menu Packing puis Nouveau packing | H2: N/A | I2: La page packings-new se charge sans erreur. | K2: NT
A3: PACK-002 | B3: Acces et navigation | C3: Controle permission | D3: P1 | E3: Securite | F3: Utilisateur sans permission packings.create | G3: Tenter acces direct URL #/packings/packings-new | H3: N/A | I3: Acces refuse (403 ou redirection autorisee). | K3: NT
A4: PACK-003 | B4: Acces et navigation | C4: Lien menu | D4: P2 | E4: Fonctionnel | F4: Utilisateur connecte | G4: Cliquer entree menu Packing puis creation | H4: N/A | I4: Le bon ecran de creation est affiche. | K4: NT
A5: PACK-004 | B5: Acces et navigation | C5: Fil d ariane | D5: P3 | E5: UX | F5: Page packings-new ouverte | G5: Verifier breadcrumb | H5: N/A | I5: Breadcrumb affiche packings / packings-new coherent. | K5: NT
A6: PACK-005 | B6: Acces et navigation | C6: Chargement initial | D6: P1 | E6: UX | F6: Page packings-new ouverte | G6: Observer formulaire au premier rendu | H6: N/A | I6: Tous les champs et libelles attendus sont visibles. | K6: NT
A7: PACK-006 | B7: Acces et navigation | C7: Champs obligatoires | D7: P1 | E7: UX | F7: Page packings-new ouverte | G7: Verifier presence indicateur obligatoire (*) | H7: N/A | I7: Les champs requis sont clairement identifies. | K7: NT
A8: PACK-007 | B8: Acces et navigation | C8: Etat bouton sauver | D8: P2 | E8: UX | F8: Page packings-new ouverte | G8: Sans renseigner les champs requis, observer bouton Enregistrer | H8: N/A | I8: Bouton desactive ou soumission bloquee avec messages clairs. | K8: NT
A9: PACK-008 | B9: Acces et navigation | C9: Navigation clavier | D9: P3 | E9: Accessibilite | F9: Page packings-new ouverte | G9: Utiliser touche Tab depuis premier champ jusqu au bouton | H9: N/A | I9: Ordre de tabulation logique et visible. | K9: NT
A10: PACK-009 | B10: Acces et navigation | C10: Responsive mobile | D10: P2 | E10: UX | F10: Navigateur en largeur 360px | G10: Ouvrir page et parcourir formulaire | H10: Viewport mobile | I10: Formulaire utilisable sans chevauchement ni champ coupe. | K10: NT
A11: PACK-010 | B11: Acces et navigation | C11: Responsive desktop | D11: P3 | E11: UX | F11: Navigateur largeur >= 1440px | G11: Ouvrir page et observer alignements | H11: Viewport desktop | I11: Alignement propre, champs lisibles, pas de zone vide anormale. | K11: NT
A12: PACK-011 | B12: Acces et navigation | C12: Rafraichissement F5 | D12: P3 | E12: Robustesse | F12: Formulaire rempli partiellement | G12: Appuyer F5 puis revenir a la page | H12: N/A | I12: Pas de crash front; comportement de reset/restauration est coherent. | K12: NT
A13: PACK-012 | B13: Acces et navigation | C13: Changement usine | D13: P1 | E13: Fonctionnel | F13: Utilisateur multi-usines avec selecteur usine visible | G13: Changer usine puis revenir sur creation packing | H13: Usine A puis Usine B | I13: Le contexte actif est pris en compte pour les donnees chargees. | K13: NT
... A36: PACK-035 | B36: Date | C36: Timezone | D36: P2 | E36: Integrite donnee | F36: Fuseau navigateur non UTC | G36: Creer packing puis verifier date retour API | H36: N/A | I36: Pas de decalage jour-1/jour+1 non desire. | K36: NT
A37: PACK-036 | B37: Date | C37: Date tres ancienne | D37: P3 | E37: Validation | F37: Formulaire valide | G37: Saisir 01/01/1970 | H37: 25569 | I37: Comportement explicite (accepte ou message metier). | K37: NT
A38: PACK-037 | B38: Date | C38: Date tres future | D38: P3 | E38: Validation | F38: Formulaire valide | G38: Saisir 01/01/2100 | H38: 73051 | I38: Comportement explicite (accepte ou message metier). | K38: NT
A39: PACK-038 | B39: Date | C39: Espaces autour date | D39: P3 | E39: Validation | F39: Saisie manuelle autorisee | G39: Entrer date avec espaces puis blur | H39: 28/02/2026 | I39: Date normalisee ou erreur claire. | K39: NT
A40: PACK-039 | B40: Date | C40: Ouverture calendrier | D40: P3 | E40: UX | F40: Champ date visible | G40: Cliquer icone calendrier | H40: N/A | I40: Datepicker s ouvre correctement. | K40: NT
A41: PACK-040 | B41: Date | C41: Saisie clavier + blur | D41: P3 | E41: UX | F41: Champ date editable | G41: Saisir date valide puis perdre focus | H41: 27/02/2026 | I41: Valeur conservee et validee. | K41: NT
A42: PACK-041 | B42: Rouleaux | C42: Valeur par defaut | D42: P1 | E42: Fonctionnel | F42: Ouvrir page creation | G42: Observer champ Rouleaux | H42: N/A | I42: Valeur initiale conforme au front (souvent 0). | K42: NT
A43: PACK-042 | B43: Rouleaux | C43: Valeur minimale positive | D43: P1 | E43: Fonctionnel | F43: Stock rouleaux >= 1 | G43: Saisir 1 puis soumettre | H43: 1 | I43: Creation acceptee. | K43: NT
A44: PACK-043 | B44: Rouleaux | C44: Limite stock exacte | D44: P1 | E44: Fonctionnel | F44: Stock connu = N | G44: Saisir N puis soumettre | H44: nb_rouleaux = stock actuel | I44: Creation acceptee avec stock resultant 0. | K44: NT
A45: PACK-044 | B45: Rouleaux | C45: Valeur zero | D45: P2 | E45: Fonctionnel | F45: Formulaire valide | G45: Saisir 0 puis soumettre | H45: 0 | I45: Creation acceptee; pas de decrement stock. | K45: NT
A46: PACK-045 | B46: Rouleaux | C46: Valeur negative front | D46: P1 | E46: Validation | F46: Champ numerique actif | G46: Entrer -1 | H46: -1 | I46: Blocage front ou message de validation. | K46: NT
A47: PACK-046 | B47: Rouleaux | C47: Valeur negative payload | D47: P1 | E47: Validation API | F47: Modifier requete via DevTools | G47: Envoyer nb_rouleaux=-1 | H47: -1 | I47: Erreur 422 min: ne peut pas etre negatif. | K47: NT
A48: PACK-047 | B48: Rouleaux | C48: Valeur decimale front | D48: P1 | E48: Validation | F48: Champ numerique actif | G48: Entrer 1.5 | H48: 1.5 | I48: Blocage front ou message entier requis. | K48: NT
A49: PACK-048 | B49: Rouleaux | C49: Valeur decimale payload | D49: P1 | E49: Validation API | F49: Modifier requete via DevTools | G49: Envoyer nb_rouleaux=1.5 | H49: 1.5 | I49: Erreur 422: doit etre un entier. | K49: NT
A50: PACK-049 | B50: Rouleaux | C50: Texte alphabetique | D50: P1 | E50: Validation | F50: Champ editable | G50: Saisir abc | H50: abc | I50: Valeur refusee par front/API. | K50: NT
A51: PACK-050 | B51: Rouleaux | C51: Texte alphanumerique | D51: P1 | E51: Validation | F51: Champ editable | G51: Saisir 12a | H51: 12a | I51: Valeur refusee. | K51: NT
A52: PACK-051 | B52: Rouleaux | C52: Espaces autour entier | D52: P3 | E52: Validation | F52: Champ editable | G52: Saisir 5 puis soumettre | H52: 5 | I52: Valeur normalisee en entier 5 ou erreur claire. | K52: NT
A53: PACK-052 | B53: Rouleaux | C53: Zeros a gauche | D53: P3 | E53: Validation | F53: Champ editable | G53: Saisir 0007 | H53: 7 | I53: Valeur interpretee en 7. | K53: NT
A54: PACK-053 | B54: Rouleaux | C54: Champ vide | D54: P1 | E54: Validation | F54: Autres champs valides | G54: Vider rouleaux puis soumettre | H54: vide | I54: Erreur: nombre de rouleaux obligatoire. | K54: NT
A55: PACK-054 | B55: Rouleaux | C55: Stock insuffisant | D55: P1 | E55: Metier | F55: Stock connu < valeur testee | G55: Saisir nb > stock puis soumettre | H55: nb_rouleaux=stock+1 | I55: Erreur metier stock insuffisant. | K55: NT
A56: PACK-055 | B56: Rouleaux | C56: Produit rouleau non configure | D56: P1 | E56: Metier | F56: Parametre produit_rouleau_id vide | G56: Saisir nb>0 puis soumettre | H56: nb_rouleaux=1 | I56: Erreur: produit rouleau non configure. | K56: NT
A57: PACK-056 | B57: Rouleaux | C57: Concurrence stock | D57: P1 | E57: Robustesse | F57: Deux utilisateurs sur meme stock limite | G57: Soumettre en parallele nb cumul > stock | H57: N/A | I57: Un des deux est refuse avec message stock insuffisant. | K57: NT
A58: PACK-057 | B58: Rouleaux | C58: Valeur tres grande | D58: P2 | E58: Robustesse | F58: Stock tres eleve en preprod | G58: Saisir valeur tres grande | H58: 1000000 | I58: Appli reste stable; validation metier coherente. | K58: NT
A59: PACK-058 | B59: Rouleaux | C59: Recalcul montant live | D59: P2 | E59: UX | F59: Prix deja renseigne | G59: Modifier nb_rouleaux | H59: ex: 3 -> 8 | I59: Montant total se met a jour immediatement. | K59: NT
A60: PACK-059 | B60: Prix par rouleau | C60: Valeur initiale | D60: P1 | E60: Fonctionnel | F60: Ouvrir page creation | G60: Observer champ Prix/rouleau | H60: N/A | I60: Valeur initiale conforme parametre ou front. | K60: NT
A61: PACK-060 | B61: Prix par rouleau | C61: Valeur zero | D61: P2 | E61: Fonctionnel | F61: Formulaire valide | G61: Saisir prix 0 puis soumettre | H61: 0 | I61: Creation acceptee avec montant calcule. | K61: NT
A62: PACK-061 | B62: Prix par rouleau | C62: Valeur 1 | D62: P1 | E62: Fonctionnel | F62: Formulaire valide | G62: Saisir prix 1 puis soumettre | H62: 1 | I62: Creation acceptee. | K62: NT
...
